Workbook

Sheet Lineal
A1: LINEAL | D1: IBM World-wide sales | G1: INTERMEDIATE CALCULATIONS: | M1: Resumen
A2: Linear regression on time | G2: RMSE (Square root of MSE) | I2: =IF(C15=0,0,SQRT(I6)) -> 71.991062
A3: Yt= a + bt | G3: 3 X RMSE | I3: =3*I2 -> 215.97319 | M3: Estadísticas de la regresión
A4: Select Tools, Data Analysis, Regression. Enter ranges as follows: | M4: Coeficiente de correlación múltiple | N4: 0.92075132
A5: Y range includes column B, X range includes column C (mismo tamaño de la columna B), Output range = M1. | G5: Warm-up SSE | I5: =VLOOKUP($C$10,$P$25:$R$120,3) -> 20730.852 | M5: Coeficiente de determinación R^2 | N5: 0.847783
A6: Ensure number of data selected for Y and X ranges agree with the | G6: Warm-up MSE | I6: =I5/$C$10 -> 5182.7131 | M6: R^2 ajustado | N6: 0.7716745
A7: nbr. of warm-up data entered in cell C10. | G7: Forecasting SSE | I7: =VLOOKUP($C$15,$P$25:$R$120,3) -> 20730.852 | M7: Error típico | N7: 101.81074
G8: Fcst SSE - Warm-up SSE | I8: =I7-I5 -> 0 | M8: Observaciones | N8: 4
A9: INPUT: | G9: Nbr. of forecast periods | I9: =$C$15-$C$10 -> 0
A10: Nbr. of warm-up data | C10: 4 | G10: Forecasting MSE | I10: =IF(I9=0,0,+I8/I9) -> 0 | M10: ANÁLISIS DE VARIANZA
A11: Last period to forecast | C11: 2046 | N11: Grados de libertad | O11: Suma de cuadrados | P11: Promedio de los cuadrados | Q11: F | R11: Valor crítico de F
G12: Warm-up Sum abs. err. | I12: =VLOOKUP($C$10,$P$25:$R$120,2) -> 247.58076 | M12: Regresión | N12: 1 | O12: 115461.9 | P12: 115461.9 | Q12: 11.139137 | R12: 0.079248678
G13: Warm-up MAD | I13: =I12/$C$10 -> 61.895189 | M13: Residuos | N13: 2 | O13: 20730.852 | P13: 10365.426
A14: OUTPUT: | G14: Forecasting Sum abs. err. | I14: =VLOOKUP($C$15,$P$25:$R$120,2) -> 247.58076 | M14: Total | N14: 3 | O14: 136192.75
A15: Number of data | C15: =COUNT(B25:B120) -> 4 | G15: Fcst Sum abs. - Warm-up Sum abs. | I15: =I14-I12 -> 0
A16: Nbr. of outliers | C16: =VLOOKUP(C15,P25:T120,5) -> 0 | G16: Nbr. of forecast periods | I16: =$C$15-$C$10 -> 0 | N16: Coeficientes | O16: Error típico | P16: Estadístico t | Q16: Probabilidad | R16: Inferior 95% | S16: Superior 95% | T16: Inferior 95.0% | U16: Superior 95.0%
A17: Warm-up MSE | C17: =IF(C10=0,0,+I6) -> 5182.7131 | G17: Forecasting MAD | I17: =IF(I16=0,0,+I15/I16) -> 0 | M17: Intercepción | N17: -34775.294 | O17: 11969.436 | P17: -2.9053411 | Q17: 0.10086286 | R17: -86275.619 | S17: 16725.032 | T17: -86275.619 | U17: 16725.032
A18: Forecasting MSE | C18: =IF(C15=0,0,+I10) -> 0 | G18: Last forecast at period | I18: =C11 -> 2046 | M18: Variable X 1 | N18: 19.919244 | O18: 5.9682511 | P18: 3.3375345 | Q18: 0.079248678 | R18: -5.7600678 | S18: 45.598556 | T18: -5.7600678 | U18: 45.598556
A19: Warm-up MAD | C19: =IF(C10=0,0,+I13) -> 61.895189
A20: Forecasting MAD | C20: =IF(C15=0,0,+I17) -> 0
B22: Regression ranges
B23: Y range | C23: X range | M23: Outlier | Q23: Sum abs | R23: Sum | S23: Outlier | T23: Sum
A24: Mon/yr. | B24: Data | C24: t | D24: Est Y | E24: e = Y - Est Y | F24: e^2 | M24: Lower control | N24: Upper control | P24: t | Q24: errors | R24: error^2 | S24: Indicator | T24: nbr outliers
A25: 1993 | B25: 4963 | C25: =IF(A25="","",A25) -> 1993 | D25: =IF(A25="","",$N$17+$N$18*C25) -> 4923.7595 | E25: =IF(A25="","",IF(B25="",NA(),B25-D25)) -> 39.24055 | F25: =IF(A25="","",IF(B25="",NA(),E25^2)) -> 1539.8208 | M25: =-$I$3 -> -215.97319 | N25: =$I$3 -> 215.97319 | P25: 1 | Q25: =ABS(E25) -> 39.24055 | R25: =E25^2 -> 1539.8208 | S25: =IF(C25>$C$15,0,IF(ABS(G25)>=$I$3,1,0)) -> 0 | T25: =SUM($S$26:S26) -> 0
A26: 2005 | B26: 5039 | C26: =IF(A26="","",A26) -> 2005 | D26: =IF(A26="","",$N$17+$N$18*C26) -> 5162.7904 | E26: =IF(A26="","",IF(B26="",NA(),B26-D26)) -> -123.79038 | F26: =IF(A26="","",IF(B26="",NA(),E26^2)) -> 15324.058 | M26: =-$I$3 -> -215.97319 | N26: =$I$3 -> 215.97319 | P26: 2 | Q26: =IF(B26="",0,+Q25+ABS(E26)) -> 163.03093 | R26: =IF(B26="",0,+R25+E26^2) -> 16863.878 | S26: =IF(C26>$C$15,0,IF(ABS(G26)>=$I$3,1,0)) -> 0 | T26: =SUM($S$26:S27) -> 0
A27: 2007 | B27: 5257 | C27: =IF(A27="","",A27) -> 2007 | D27: =IF(A27="","",$N$17+$N$18*C27) -> 5202.6289 | E27: =IF(A27="","",IF(B27="",NA(),B27-D27)) -> 54.371134 | F27: =IF(A27="","",IF(B27="",NA(),E27^2)) -> 2956.2202 | M27: =-$I$3 -> -215.97319 | N27: =$I$3 -> 215.97319 | P27: 3 | Q27: =IF(B27="",0,+Q26+ABS(E27)) -> 217.40206 | R27: =IF(B27="",0,+R26+E27^2) -> 19820.099 | S27: =IF(C27>$C$15,0,IF(ABS(G27)>=$I$3,1,0)) -> 0 | T27: =SUM($S$26:S28) -> 0
A28: 2017 | B28: 5432 | C28: =IF(A28="","",A28) -> 2017 | D28: =IF(A28="","",$N$17+$N$18*C28) -> 5401.8213 | E28: =IF(A28="","",IF(B28="",NA(),B28-D28)) -> 30.178694 | F28: =IF(A28="","",IF(B28="",NA(),E28^2)) -> 910.75358 | M28: =-$I$3 -> -215.97319 | N28: =$I$3 -> 215.97319 | P28: 4 | Q28: =IF(B28="",0,+Q27+ABS(E28)) -> 247.58076 | R28: =IF(B28="",0,+R27+E28^2) -> 20730.852 | S28: =IF(C28>$C$15,0,IF(ABS(G28)>=$I$3,1,0)) -> 0 | T28: =SUM($S$26:S29) -> 0
A29: 2026 | C29: =IF(A29="","",A29) -> 2026 | D29: =IF(A29="","",$N$17+$N$18*C29) -> 5581.0945 | E29: =IF(A29="","",IF(B29="",NA(),B29-D29)) -> #N/A | F29: =IF(A29="","",IF(B29="",NA(),E29^2)) -> #N/A | M29: =-$I$3 -> -215.97319 | N29: =$I$3 -> 215.97319 | P29: 5 | Q29: =IF(B29="",0,+Q28+ABS(E29)) -> 0 | R29: =IF(B29="",0,+R28+E29^2) -> 0 | S29: =IF(C29>$C$15,0,IF(ABS(G29)>=$I$3,1,0)) -> 0 | T29: =SUM($S$26:S30) -> 0
A30: 2036 | C30: =IF(A30="","",A30) -> 2036 | D30: =IF(A30="","",$N$17+$N$18*C30) -> 5780.2869 | E30: =IF(A30="","",IF(B30="",NA(),B30-D30)) -> #N/A | F30: =IF(A30="","",IF(B30="",NA(),E30^2)) -> #N/A | M30: =-$I$3 -> -215.97319 | N30: =$I$3 -> 215.97319 | P30: 6 | Q30: =IF(B30="",0,+Q29+ABS(E30)) -> 0 | R30: =IF(B30="",0,+R29+E30^2) -> 0 | S30: =IF(C30>$C$15,0,IF(ABS(G30)>=$I$3,1,0)) -> 0 | T30: =SUM($S$26:S31) -> 0
A31: 2046 | C31: =IF(A31="","",A31) -> 2046 | D31: =IF(A31="","",$N$17+$N$18*C31) -> 5979.4794 | E31: =IF(A31="","",IF(B31="",NA(),B31-D31)) -> #N/A | F31: =IF(A31="","",IF(B31="",NA(),E31^2)) -> #N/A | M31: =-$I$3 -> -215.97319 | N31: =$I$3 -> 215.97319 | P31: 7 | Q31: =IF(B31="",0,+Q30+ABS(E31)) -> 0 | R31: =IF(B31="",0,+R30+E31^2) -> 0 | S31: =IF(C31>$C$15,0,IF(ABS(G31)>=$I$3,1,0)) -> 0 | T31: =SUM($S$26:S32) -> 0
C32: =IF(A32="","",A32) | D32: =IF(A32="","",$N$17+$N$18*C32) | E32: =IF(A32="","",IF(B32="",NA(),B32-D32)) | F32: =IF(A32="","",IF(B32="",NA(),E32^2)) | M32: =-$I$3 -> -215.97319 | N32: =$I$3 -> 215.97319 | P32: 8 | Q32: =IF(B32="",0,+Q31+ABS(E32)) -> 0 | R32: =IF(B32="",0,+R31+E32^2) -> 0 | S32: =IF(C32>$C$15,0,IF(ABS(G32)>=$I$3,1,0)) -> 0 | T32: =SUM($S$26:S33) -> 0
C33: =IF(A33="","",A33) | D33: =IF(A33="","",$N$17+$N$18*C33) | E33: =IF(A33="","",IF(B33="",NA(),B33-D33)) | F33: =IF(A33="","",IF(B33="",NA(),E33^2)) | M33: =-$I$3 -> -215.97319 | N33: =$I$3 -> 215.97319 | P33: 9 | Q33: =IF(B33="",0,+Q32+ABS(E33)) -> 0 | R33: =IF(B33="",0,+R32+E33^2) -> 0 | S33: =IF(C33>$C$15,0,IF(ABS(G33)>=$I$3,1,0)) -> 0 | T33: =SUM($S$26:S34) -> 0
C34: =IF(A34="","",A34) | D34: =IF(A34="","",$N$17+$N$18*C34) | E34: =IF(A34="","",IF(B34="",NA(),B34-D34)) | F34: =IF(A34="","",IF(B34="",NA(),E34^2)) | M34: =-$I$3 -> -215.97319 | N34: =$I$3 -> 215.97319 | P34: 10 | Q34: =IF(B34="",0,+Q33+ABS(E34)) -> 0 | R34: =IF(B34="",0,+R33+E34^2) -> 0 | S34: =IF(C34>$C$15,0,IF(ABS(G34)>=$I$3,1,0)) -> 0 | T34: =SUM($S$26:S35) -> 0
C35: =IF(A35="","",A35) | D35: =IF(A35="","",$N$17+$N$18*C35) | E35: =IF(A35="","",IF(B35="",NA(),B35-D35)) | F35: =IF(A35="","",IF(B35="",NA(),E35^2)) | M35: =-$I$3 -> -215.97319 | N35: =$I$3 -> 215.97319 | P35: 11 | Q35: =IF(B35="",0,+Q34+ABS(E35)) -> 0 | R35: =IF(B35="",0,+R34+E35^2) -> 0 | S35: =IF(C35>$C$15,0,IF(ABS(G35)>=$I$3,1,0)) -> 0 | T35: =SUM($S$26:S36) -> 0
C36: =IF(A36="","",A36) | D36: =IF(A36="","",$N$17+$N$18*C36) | E36: =IF(A36="","",IF(B36="",NA(),B36-D36)) | F36: =IF(A36="","",IF(B36="",NA(),E36^2)) | M36: =-$I$3 -> -215.97319 | N36: =$I$3 -> 215.97319 | P36: 12 | Q36: =IF(B36="",0,+Q35+ABS(E36)) -> 0 | R36: =IF(B36="",0,+R35+E36^2) -> 0 | S36: =IF(C36>$C$15,0,IF(ABS(G36)>=$I$3,1,0)) -> 0 | T36: =SUM($S$26:S37) -> 0
C37: =IF(A37="","",A37) | D37: =IF(A37="","",$N$17+$N$18*C37) | E37: =IF(A37="","",IF(B37="",NA(),B37-D37)) | F37: =IF(A37="","",IF(B37="",NA(),E37^2)) | M37: =-$I$3 -> -215.97319 | N37: =$I$3 -> 215.97319 | P37: 13 | Q37: =IF(B37="",0,+Q36+ABS(E37)) -> 0 | R37: =IF(B37="",0,+R36+E37^2) -> 0 | S37: =IF(C37>$C$15,0,IF(ABS(G37)>=$I$3,1,0)) -> 0 | T37: =SUM($S$26:S38) -> 0
C38: =IF(A38="","",A38) | D38: =IF(A38="","",$N$17+$N$18*C38) | E38: =IF(A38="","",IF(B38="",NA(),B38-D38)) | F38: =IF(A38="","",IF(B38="",NA(),E38^2)) | M38: =-$I$3 -> -215.97319 | N38: =$I$3 -> 215.97319 | P38: 14 | Q38: =IF(B38="",0,+Q37+ABS(E38)) -> 0 | R38: =IF(B38="",0,+R37+E38^2) -> 0 | S38: =IF(C38>$C$15,0,IF(ABS(G38)>=$I$3,1,0)) -> 0 | T38: =SUM($S$26:S39) -> 0
C39: =IF(A39="","",A39) | D39: =IF(A39="","",$N$17+$N$18*C39) | E39: =IF(A39="","",IF(B39="",NA(),B39-D39)) | F39: =IF(A39="","",IF(B39="",NA(),E39^2)) | M39: =-$I$3 -> -215.97319 | N39: =$I$3 -> 215.97319 | P39: 15 | Q39: =IF(B39="",0,+Q38+ABS(E39)) -> 0 | R39: =IF(B39="",0,+R38+E39^2) -> 0 | S39: =IF(C39>$C$15,0,IF(ABS(G39)>=$I$3,1,0)) -> 0 | T39: =SUM($S$26:S40) -> 0
C40: =IF(A40="","",A40) | D40: =IF(A40="","",$N$17+$N$18*C40) | E40: =IF(A40="","",IF(B40="",NA(),B40-D40)) | F40: =IF(A40="","",IF(B40="",NA(),E40^2)) | M40: =-$I$3 -> -215.97319 | N40: =$I$3 -> 215.97319 | P40: 16 | Q40: =IF(B40="",0,+Q39+ABS(E40)) -> 0 | R40: =IF(B40="",0,+R39+E40^2) -> 0 | S40: =IF(C40>$C$15,0,IF(ABS(G40)>=$I$3,1,0)) -> 0 | T40: =SUM($S$26:S41) -> 0
C41: =IF(A41="","",A41) | D41: =IF(A41="","",$N$17+$N$18*C41) | E41: =IF(A41="","",IF(B41="",NA(),B41-D41)) | F41: =IF(A41="","",IF(B41="",NA(),E41^2)) | M41: =-$I$3 -> -215.97319 | N41: =$I$3 -> 215.97319 | P41: 17 | Q41: =IF(B41="",0,+Q40+ABS(E41)) -> 0 | R41: =IF(B41="",0,+R40+E41^2) -> 0 | S41: =IF(C41>$C$15,0,IF(ABS(G41)>=$I$3,1,0)) -> 0 | T41: =SUM($S$26:S42) -> 0
...

Sheet Potencial
A1: POTENCIAL | D1: IBM World-wide sales | G1: INTERMEDIATE CALCULATIONS: | M1: Resumen
A2: Ponential regression on time | G2: RMSE (Square root of MSE) | I2: =IF(C15=0,0,SQRT(I6)) -> 70.860574
A3: ln(Y) = a + b*ln(t) | G3: 3 X RMSE | I3: =3*I2 -> 212.58172 | M3: Estadísticas de la regresión
A4: Select Tools, Data Analysis, Regression. Enter ranges as follows: | M4: Coeficiente de correlación múltiple | N4: 0.92109976
A5: Y range includes column E, X range includes column D (mismo tamaño de la columna E), Output range = M1. | G5: Warm-up SSE | I5: =VLOOKUP($C$10,$P$25:$R$120,3) -> 20084.884 | M5: Coeficiente de determinación R^2 | N5: 0.84842476
A6: Ensure number of data selected for Y and X ranges agree with the | G6: Warm-up MSE | I6: =I5/$C$10 -> 5021.221 | M6: R^2 ajustado | N6: 0.77263714
A7: nbr. of warm-up data entered in cell C10. | G7: Forecasting SSE | I7: =VLOOKUP($C$15,$P$25:$R$120,3) -> 20084.884 | M7: Error típico | N7: 0.019564688
G8: Fcst SSE - Warm-up SSE | I8: =I7-I5 -> 0 | M8: Observaciones | N8: 4
A9: INPUT: | G9: Nbr. of forecast periods | I9: =$C$15-$C$10 -> 0
A10: Nbr. of warm-up data | C10: 4 | G10: Forecasting MSE | I10: =IF(I9=0,0,+I8/I9) -> 0 | M10: ANÁLISIS DE VARIANZA
A11: Last period to forecast | C11: 2046 | N11: Grados de libertad | O11: Suma de cuadrados | P11: Promedio de los cuadrados | Q11: F | R11: Valor crítico de F
G12: Warm-up Sum abs. err. | I12: =VLOOKUP($C$10,$P$25:$R$120,2) -> 243.89538 | M12: Regresión | N12: 1 | O12: 0.0042850996 | P12: 0.0042850996 | Q12: 11.194767 | R12: 0.078900243
G13: Warm-up MAD | I13: =I12/$C$10 -> 60.973844 | M13: Residuos | N13: 2 | O13: 0.00076555403 | P13: 0.00038277702
A14: OUTPUT: | G14: Forecasting Sum abs. err. | I14: =VLOOKUP($C$15,$P$25:$R$120,2) -> 243.89538 | M14: Total | N14: 3 | O14: 0.0050506537
A15: Number of data | C15: =COUNT(B25:B120) -> 4 | G15: Fcst Sum abs. - Warm-up Sum abs. | I15: =I14-I12 -> 0
A16: Nbr. of outliers | C16: =VLOOKUP(C15,P25:T120,5) -> 0 | G16: Nbr. of forecast periods | I16: =$C$15-$C$10 -> 0 | N16: Coeficientes | O16: Error típico | P16: Estadístico t | Q16: Probabilidad | R16: Inferior 95% | S16: Superior 95% | T16: Inferior 95.0% | U16: Superior 95.0%
A17: Warm-up MSE | C17: =IF(C10=0,0,+I6) -> 5021.221 | G17: Forecasting MAD | I17: =IF(I16=0,0,+I15/I16) -> 0 | M17: Intercepción | N17: -49.943625 | O17: 17.482558 | P17: -2.8567687 | Q17: 0.10380167 | R17: -125.165 | S17: 25.277751 | T17: -125.165 | U17: 25.277751
A18: Forecasting MSE | C18: =IF(C15=0,0,+I10) -> 0 | G18: Last forecast at period | I18: =C11 -> 2046 | M18: Variable X 1 | N18: 7.6929148 | O18: 2.2992351 | P18: 3.3458582 | Q18: 0.078900243 | R18: -2.1998955 | S18: 17.585725 | T18: -2.1998955 | U18: 17.585725
A19: Warm-up MAD | C19: =IF(C10=0,0,+I13) -> 60.973844
A20: Forecasting MAD | C20: =IF(C15=0,0,+I17) -> 0
D22: Regression ranges
D23: X range | E23: Y range | M23: Outlier | Q23: Sum abs | R23: Sum | S23: Outlier | T23: Sum
A24: Mon/yr. | B24: Data | C24: t | D24: ln(t) | E24: ln(Y) | F24: Est ln(Y) | G24: Est Y | H24: e = Y - Est Y | I24: e^2 | M24: Lower control | N24: Upper control | P24: t | Q24: errors | R24: error^2 | S24: Indicator | T24: nbr outliers
A25: 1993 | B25: 4963 | C25: =IF(A25="","",A25) -> 1993 | D25: =IF(A25="","",LN(C25)) -> 7.5973963 | E25: =IF(A25="","",IF(B25="",NA(),LN(B25))) -> 8.5097657 | F25: =IF(A25="","",$N$17+$N$18*D25) -> 8.5024975 | G25: =IF(A25="","",EXP(F25)) -> 4927.0587 | H25: =IF(A25="","",IF(B25="",NA(),B25-G25)) -> 35.941346 | I25: =IF(A25="","",IF(B25="",NA(),H25^2)) -> 1291.7803 | M25: =-$I$3 -> -212.58172 | N25: =$I$3 -> 212.58172 | P25: 1 | Q25: =ABS(H25) -> 35.941346 | R25: =H25^2 -> 1291.7803 | S25: =IF(C25>$C$15,0,IF(ABS(H25)>=$I$3,1,0)) -> 0 | T25: =SUM($S$26:S26) -> 0
A26: 2005 | B26: 5039 | C26: =IF(A26="","",A26) -> 2005 | D26: =IF(A26="","",LN(C26)) -> 7.6033993 | E26: =IF(A26="","",IF(B26="",NA(),LN(B26))) -> 8.5249629 | F26: =IF(A26="","",$N$17+$N$18*D26) -> 8.5486782 | G26: =IF(A26="","",EXP(F26)) -> 5159.9294 | H26: =IF(A26="","",IF(B26="",NA(),B26-G26)) -> -120.92944 | I26: =IF(A26="","",IF(B26="",NA(),H26^2)) -> 14623.93 | M26: =-$I$3 -> -212.58172 | N26: =$I$3 -> 212.58172 | P26: 2 | Q26: =IF(B26="",0,+Q25+ABS(H26)) -> 156.87079 | R26: =IF(B26="",0,+R25+H26^2) -> 15915.711 | S26: =IF(C26>$C$15,0,IF(ABS(H26)>=$I$3,1,0)) -> 0 | T26: =SUM($S$26:S27) -> 0
A27: 2007 | B27: 5257 | C27: =IF(A27="","",A27) -> 2007 | D27: =IF(A27="","",LN(C27)) -> 7.6043963 | E27: =IF(A27="","",IF(B27="",NA(),LN(B27))) -> 8.5673158 | F27: =IF(A27="","",$N$17+$N$18*D27) -> 8.5563481 | G27: =IF(A27="","",EXP(F27)) -> 5199.6578 | H27: =IF(A27="","",IF(B27="",NA(),B27-G27)) -> 57.342222 | I27: =IF(A27="","",IF(B27="",NA(),H27^2)) -> 3288.1305 | M27: =-$I$3 -> -212.58172 | N27: =$I$3 -> 212.58172 | P27: 3 | Q27: =IF(B27="",0,+Q26+ABS(H27)) -> 214.21301 | R27: =IF(B27="",0,+R26+H27^2) -> 19203.841 | S27: =IF(C27>$C$15,0,IF(ABS(H27)>=$I$3,1,0)) -> 0 | T27: =SUM($S$26:S28) -> 0
A28: 2017 | B28: 5432 | C28: =IF(A28="","",A28) -> 2017 | D28: =IF(A28="","",LN(C28)) -> 7.6093665 | E28: =IF(A28="","",IF(B28="",NA(),LN(B28))) -> 8.6000627 | F28: =IF(A28="","",$N$17+$N$18*D28) -> 8.5945833 | G28: =IF(A28="","",EXP(F28)) -> 5402.3176 | H28: =IF(A28="","",IF(B28="",NA(),B28-G28)) -> 29.682365 | I28: =IF(A28="","",IF(B28="",NA(),H28^2)) -> 881.04282 | M28: =-$I$3 -> -212.58172 | N28: =$I$3 -> 212.58172 | P28: 4 | Q28: =IF(B28="",0,+Q27+ABS(H28)) -> 243.89538 | R28: =IF(B28="",0,+R27+H28^2) -> 20084.884 | S28: =IF(C28>$C$15,0,IF(ABS(H28)>=$I$3,1,0)) -> 0 | T28: =SUM($S$26:S29) -> 0
A29: 2026 | C29: =IF(A29="","",A29) -> 2026 | D29: =IF(A29="","",LN(C29)) -> 7.6138187 | E29: =IF(A29="","",IF(B29="",NA(),LN(B29))) -> #N/A | F29: =IF(A29="","",$N$17+$N$18*D29) -> 8.6288333 | G29: =IF(A29="","",EXP(F29)) -> 5590.5521 | H29: =IF(A29="","",IF(B29="",NA(),B29-G29)) -> #N/A | I29: =IF(A29="","",IF(B29="",NA(),H29^2)) -> #N/A | M29: =-$I$3 -> -212.58172 | N29: =$I$3 -> 212.58172 | P29: 5 | Q29: =IF(B29="",0,+Q28+ABS(H29)) -> 0 | R29: =IF(B29="",0,+R28+H29^2) -> 0 | S29: =IF(C29>$C$15,0,IF(ABS(H29)>=$I$3,1,0)) -> 0 | T29: =SUM($S$26:S30) -> 0
A30: 2036 | C30: =IF(A30="","",A30) -> 2036 | D30: =IF(A30="","",LN(C30)) -> 7.6187424 | E30: =IF(A30="","",IF(B30="",NA(),LN(B30))) -> #N/A | F30: =IF(A30="","",$N$17+$N$18*D30) -> 8.6667109 | G30: =IF(A30="","",EXP(F30)) -> 5806.37 | H30: =IF(A30="","",IF(B30="",NA(),B30-G30)) -> #N/A | I30: =IF(A30="","",IF(B30="",NA(),H30^2)) -> #N/A | M30: =-$I$3 -> -212.58172 | N30: =$I$3 -> 212.58172 | P30: 6 | Q30: =IF(B30="",0,+Q29+ABS(H30)) -> 0 | R30: =IF(B30="",0,+R29+H30^2) -> 0 | S30: =IF(C30>$C$15,0,IF(ABS(H30)>=$I$3,1,0)) -> 0 | T30: =SUM($S$26:S31) -> 0
A31: 2046 | C31: =IF(A31="","",A31) -> 2046 | D31: =IF(A31="","",LN(C31)) -> 7.6236419 | E31: =IF(A31="","",IF(B31="",NA(),LN(B31))) -> #N/A | F31: =IF(A31="","",$N$17+$N$18*D31) -> 8.7044028 | G31: =IF(A31="","",EXP(F31)) -> 6029.4003 | H31: =IF(A31="","",IF(B31="",NA(),B31-G31)) -> #N/A | I31: =IF(A31="","",IF(B31="",NA(),H31^2)) -> #N/A | M31: =-$I$3 -> -212.58172 | N31: =$I$3 -> 212.58172 | P31: 7 | Q31: =IF(B31="",0,+Q30+ABS(H31)) -> 0 | R31: =IF(B31="",0,+R30+H31^2) -> 0 | S31: =IF(C31>$C$15,0,IF(ABS(H31)>=$I$3,1,0)) -> 0 | T31: =SUM($S$26:S32) -> 0
C32: =IF(A32="","",A32) | D32: =IF(A32="","",LN(C32)) | E32: =IF(A32="","",IF(B32="",NA(),LN(B32))) | F32: =IF(A32="","",$N$17+$N$18*D32) | G32: =IF(A32="","",EXP(F32)) | H32: =IF(A32="","",IF(B32="",NA(),B32-G32)) | I32: =IF(A32="","",IF(B32="",NA(),H32^2)) | M32: =-$I$3 -> -212.58172 | N32: =$I$3 -> 212.58172 | P32: 8 | Q32: =IF(B32="",0,+Q31+ABS(H32)) -> 0 | R32: =IF(B32="",0,+R31+H32^2) -> 0 | S32: =IF(C32>$C$15,0,IF(ABS(H32)>=$I$3,1,0)) -> 0 | T32: =SUM($S$26:S33) -> 0
C33: =IF(A33="","",A33) | E33: =IF(A33="","",IF(B33="",NA(),LN(B33))) | F33: =IF(A33="","",$N$17+$N$18*D33) | G33: =IF(A33="","",EXP(F33)) | H33: =IF(A33="","",IF(B33="",NA(),B33-G33)) | I33: =IF(A33="","",IF(B33="",NA(),H33^2)) | M33: =-$I$3 -> -212.58172 | N33: =$I$3 -> 212.58172 | P33: 9 | Q33: =IF(B33="",0,+Q32+ABS(H33)) -> 0 | R33: =IF(B33="",0,+R32+H33^2) -> 0 | S33: =IF(C33>$C$15,0,IF(ABS(H33)>=$I$3,1,0)) -> 0 | T33: =SUM($S$26:S34) -> 0
C34: =IF(A34="","",A34) | E34: =IF(A34="","",IF(B34="",NA(),LN(B34))) | F34: =IF(A34="","",$N$17+$N$18*D34) | G34: =IF(A34="","",EXP(F34)) | H34: =IF(A34="","",IF(B34="",NA(),B34-G34)) | I34: =IF(A34="","",IF(B34="",NA(),H34^2)) | M34: =-$I$3 -> -212.58172 | N34: =$I$3 -> 212.58172 | P34: 10 | Q34: =IF(C34>$C$15,0,+Q33+ABS(H34)) -> 0 | R34: =IF(B34="",0,+R33+H34^2) -> 0 | S34: =IF(C34>$C$15,0,IF(ABS(H34)>=$I$3,1,0)) -> 0 | T34: =SUM($S$26:S35) -> 0
C35: =IF(A35="","",A35) | E35: =IF(A35="","",IF(B35="",NA(),LN(B35))) | F35: =IF(A35="","",$N$17+$N$18*D35) | G35: =IF(A35="","",EXP(F35)) | H35: =IF(A35="","",IF(B35="",NA(),B35-G35)) | I35: =IF(A35="","",IF(B35="",NA(),H35^2)) | M35: =-$I$3 -> -212.58172 | N35: =$I$3 -> 212.58172 | P35: 11 | Q35: =IF(C35>$C$15,0,+Q34+ABS(H35)) -> 0 | R35: =IF(B35="",0,+R34+H35^2) -> 0 | S35: =IF(C35>$C$15,0,IF(ABS(H35)>=$I$3,1,0)) -> 0 | T35: =SUM($S$26:S36) -> 0
C36: =IF(A36="","",A36) | E36: =IF(A36="","",IF(B36="",NA(),LN(B36))) | F36: =IF(A36="","",$N$17+$N$18*D36) | G36: =IF(A36="","",EXP(F36)) | H36: =IF(A36="","",IF(B36="",NA(),B36-G36)) | I36: =IF(A36="","",IF(B36="",NA(),H36^2)) | M36: =-$I$3 -> -212.58172 | N36: =$I$3 -> 212.58172 | P36: 12 | Q36: =IF(C36>$C$15,0,+Q35+ABS(H36)) -> 0 | R36: =IF(B36="",0,+R35+H36^2) -> 0 | S36: =IF(C36>$C$15,0,IF(ABS(H36)>=$I$3,1,0)) -> 0 | T36: =SUM($S$26:S37) -> 0
C37: =IF(A37="","",A37) | E37: =IF(A37="","",IF(B37="",NA(),LN(B37))) | F37: =IF(A37="","",$N$17+$N$18*D37) | G37: =IF(A37="","",EXP(F37)) | H37: =IF(A37="","",IF(B37="",NA(),B37-G37)) | I37: =IF(A37="","",IF(B37="",NA(),H37^2)) | M37: =-$I$3 -> -212.58172 | N37: =$I$3 -> 212.58172 | P37: 13 | Q37: =IF(C37>$C$15,0,+Q36+ABS(H37)) -> 0 | R37: =IF(B37="",0,+R36+H37^2) -> 0 | S37: =IF(C37>$C$15,0,IF(ABS(H37)>=$I$3,1,0)) -> 0 | T37: =SUM($S$26:S38) -> 0
C38: =IF(A38="","",A38) | E38: =IF(A38="","",IF(B38="",NA(),LN(B38))) | F38: =IF(A38="","",$N$17+$N$18*D38) | G38: =IF(A38="","",EXP(F38)) | H38: =IF(A38="","",IF(B38="",NA(),B38-G38)) | I38: =IF(A38="","",IF(B38="",NA(),H38^2)) | M38: =-$I$3 -> -212.58172 | N38: =$I$3 -> 212.58172 | P38: 14 | Q38: =IF(C38>$C$15,0,+Q37+ABS(H38)) -> 0 | R38: =IF(B38="",0,+R37+H38^2) -> 0 | S38: =IF(C38>$C$15,0,IF(ABS(H38)>=$I$3,1,0)) -> 0 | T38: =SUM($S$26:S39) -> 0
C39: =IF(A39="","",A39) | E39: =IF(A39="","",IF(B39="",NA(),LN(B39))) | F39: =IF(A39="","",$N$17+$N$18*D39) | G39: =IF(A39="","",EXP(F39)) | H39: =IF(A39="","",IF(B39="",NA(),B39-G39)) | I39: =IF(A39="","",IF(B39="",NA(),H39^2)) | M39: =-$I$3 -> -212.58172 | N39: =$I$3 -> 212.58172 | P39: 15 | Q39: =IF(C39>$C$15,0,+Q38+ABS(H39)) -> 0 | R39: =IF(B39="",0,+R38+H39^2) -> 0 | S39: =IF(C39>$C$15,0,IF(ABS(H39)>=$I$3,1,0)) -> 0 | T39: =SUM($S$26:S40) -> 0
C40: =IF(A40="","",A40) | E40: =IF(A40="","",IF(B40="",NA(),LN(B40))) | F40: =IF(A40="","",$N$17+$N$18*D40) | G40: =IF(A40="","",EXP(F40)) | H40: =IF(A40="","",IF(B40="",NA(),B40-G40)) | I40: =IF(A40="","",IF(B40="",NA(),H40^2)) | M40: =-$I$3 -> -212.58172 | N40: =$I$3 -> 212.58172 | P40: 16 | Q40: =IF(C40>$C$15,0,+Q39+ABS(H40)) -> 0 | R40: =IF(B40="",0,+R39+H40^2) -> 0 | S40: =IF(C40>$C$15,0,IF(ABS(H40)>=$I$3,1,0)) -> 0 | T40: =SUM($S$26:S41) -> 0
C41: =IF(A41="","",A41) | E41: =IF(A41="","",IF(B41="",NA(),LN(B41))) | F41: =IF(A41="","",$N$17+$N$18*D41) | G41: =IF(A41="","",EXP(F41)) | H41: =IF(A41="","",IF(B41="",NA(),B41-G41)) | I41: =IF(A41="","",IF(B41="",NA(),H41^2)) | M41: =-$I$3 -> -212.58172 | N41: =$I$3 -> 212.58172 | P41: 17 | Q41: =IF(C41>$C$15,0,+Q40+ABS(H41)) -> 0 | R41: =IF(B41="",0,+R40+H41^2) -> 0 | S41: =IF(C41>$C$15,0,IF(ABS(H41)>=$I$3,1,0)) -> 0 | T41: =SUM($S$26:S42) -> 0
...

Sheet Exponencial
A1: EXPONENCIAL | D1: IBM World-wide sales | G1: INTERMEDIATE CALCULATIONS: | M1: Resumen
A2: Exponential regression on time | G2: RMSE (Square root of MSE) | I2: =IF(C15=0,0,SQRT(I6)) -> 70.69318
A3: ln(Yt) = a + bt | G3: 3 X RMSE | I3: =3*I2 -> 212.07954 | M3: Estadísticas de la regresión
A4: Select Tools, Data Analysis, Regression. Enter ranges as follows: | M4: Coeficiente de correlación múltiple | N4: 0.92148461
A5: Y range includes column D, X range includes column C (mismo tamaño de la columna D), Output range = M1. | G5: Warm-up SSE | I5: =VLOOKUP($C$10,$P$25:$R$120,3) -> 19990.103 | M5: Coeficiente de determinación R^2 | N5: 0.84913389
A6: Ensure number of data selected for Y and X ranges agree with the | G6: Warm-up MSE | I6: =I5/$C$10 -> 4997.5257 | M6: R^2 ajustado | N6: 0.77370083
A7: nbr. of warm-up data entered in cell C10. | G7: Forecasting SSE | I7: =VLOOKUP($C$15,$P$25:$R$120,3) -> 19990.103 | M7: Error típico | N7: 0.019518869
G8: Fcst SSE - Warm-up SSE | I8: =I7-I5 -> 0 | M8: Observaciones | N8: 4
A9: INPUT: | G9: Nbr. of forecast periods | I9: =$C$15-$C$10 -> 0
A10: Nbr. of warm-up data | C10: 4 | G10: Forecasting MSE | I10: =IF(I9=0,0,+I8/I9) -> 0 | M10: ANÁLISIS DE VARIANZA
A11: Last period to forecast | C11: 2046 | N11: Grados de libertad | O11: Suma de cuadrados | P11: Promedio de los cuadrados | Q11: F | R11: Valor crítico de F
G12: Warm-up Sum abs. err. | I12: =VLOOKUP($C$10,$P$25:$R$120,2) -> 243.15372 | M12: Regresión | N12: 1 | O12: 0.0042886812 | P12: 0.0042886812 | Q12: 11.256787 | R12: 0.078515391
G13: Warm-up MAD | I13: =I12/$C$10 -> 60.788429 | M13: Residuos | N13: 2 | O13: 0.00076197249 | P13: 0.00038098625
A14: OUTPUT: | G14: Forecasting Sum abs. err. | I14: =VLOOKUP($C$15,$P$25:$R$120,2) -> 243.15372 | M14: Total | N14: 3 | O14: 0.0050506537
A15: Number of data | C15: =COUNT(B25:B120) -> 4 | G15: Fcst Sum abs. - Warm-up Sum abs. | I15: =I14-I12 -> 0
A16: Nbr. of outliers | C16: =VLOOKUP(C15,P25:T120,5) -> 0 | G16: Nbr. of forecast periods | I16: =$C$15-$C$10 -> 0 | N16: Coeficientes | O16: Error típico | P16: Estadístico t | Q16: Probabilidad | R16: Inferior 95% | S16: Superior 95% | T16: Inferior 95.0% | U16: Superior 95.0%
A17: Warm-up MSE | C17: =IF(C10=0,0,+I6) -> 4997.5257 | G17: Forecasting MAD | I17: =IF(I16=0,0,+I15/I16) -> 0 | M17: Intercepción | N17: 0.85146059 | O17: 2.2947467 | P17: 0.37104775 | Q17: 0.74621917 | R17: -9.0220374 | S17: 10.724959 | T17: -9.0220374 | U17: 10.724959
A18: Forecasting MSE | C18: =IF(C15=0,0,+I10) -> 0 | G18: Last forecast at period | I18: =C11 -> 2046 | M18: Variable X 1 | N18: 0.0038389759 | O18: 0.0011442164 | P18: 3.3551136 | Q18: 0.078515391 | R18: -0.0010841898 | S18: 0.0087621416 | T18: -0.0010841898 | U18: 0.0087621416
A19: Warm-up MAD | C19: =IF(C10=0,0,+I13) -> 60.788429
A20: Forecasting MAD | C20: =IF(C15=0,0,+I17) -> 0
C22: Regression ranges
C23: X range | D23: Y range | M23: Outlier | Q23: Sum abs | R23: Sum | S23: Outlier | T23: Sum
A24: Mon/yr. | B24: Data | C24: t | D24: ln(Y) | E24: Est ln(Y) | F24: Est Y | G24: e = Y - Est Y | H24: e^2 | M24: Lower control | N24: Upper control | P24: t | Q24: errors | R24: error^2 | S24: Indicator | T24: nbr outliers
A25: 1993 | B25: 4963 | C25: =IF(A25="","",A25) -> 1993 | D25: =IF(A25="","",IF(B25="",NA(),LN(B25))) -> 8.5097657 | E25: =IF(A25="","",$N$17+$N$18*C25) -> 8.5025396 | F25: =IF(A25="","",EXP(E25)) -> 4927.2661 | G25: =IF(A25="","",IF(B25="",NA(),B25-F25)) -> 35.733899 | H25: =IF(A25="","",IF(B25="",NA(),G25^2)) -> 1276.9116 | M25: =-$I$3 -> -212.07954 | N25: =$I$3 -> 212.07954 | P25: 1 | Q25: =ABS(G25) -> 35.733899 | R25: =G25^2 -> 1276.9116 | S25: =IF(C25>$C$15,0,IF(ABS(G25)>=$I$3,1,0)) -> 0 | T25: =SUM($S$26:S26) -> 0
A26: 2005 | B26: 5039 | C26: =IF(A26="","",A26) -> 2005 | D26: =IF(A26="","",IF(B26="",NA(),LN(B26))) -> 8.5249629 | E26: =IF(A26="","",$N$17+$N$18*C26) -> 8.5486073 | F26: =IF(A26="","",EXP(E26)) -> 5159.5636 | G26: =IF(A26="","",IF(B26="",NA(),B26-F26)) -> -120.5636 | H26: =IF(A26="","",IF(B26="",NA(),G26^2)) -> 14535.581 | M26: =-$I$3 -> -212.07954 | N26: =$I$3 -> 212.07954 | P26: 2 | Q26: =IF(B26="",0,+Q25+ABS(G26)) -> 156.2975 | R26: =IF(B26="",0,+R25+G26^2) -> 15812.492 | S26: =IF(C26>$C$15,0,IF(ABS(G26)>=$I$3,1,0)) -> 0 | T26: =SUM($S$26:S27) -> 0
A27: 2007 | B27: 5257 | C27: =IF(A27="","",A27) -> 2007 | D27: =IF(A27="","",IF(B27="",NA(),LN(B27))) -> 8.5673158 | E27: =IF(A27="","",$N$17+$N$18*C27) -> 8.5562852 | F27: =IF(A27="","",EXP(E27)) -> 5199.3309 | G27: =IF(A27="","",IF(B27="",NA(),B27-F27)) -> 57.669052 | H27: =IF(A27="","",IF(B27="",NA(),G27^2)) -> 3325.7196 | M27: =-$I$3 -> -212.07954 | N27: =$I$3 -> 212.07954 | P27: 3 | Q27: =IF(B27="",0,+Q26+ABS(G27)) -> 213.96655 | R27: =IF(B27="",0,+R26+G27^2) -> 19138.212 | S27: =IF(C27>$C$15,0,IF(ABS(G27)>=$I$3,1,0)) -> 0 | T27: =SUM($S$26:S28) -> 0
A28: 2017 | B28: 5432 | C28: =IF(A28="","",A28) -> 2017 | D28: =IF(A28="","",IF(B28="",NA(),LN(B28))) -> 8.6000627 | E28: =IF(A28="","",$N$17+$N$18*C28) -> 8.594675 | F28: =IF(A28="","",EXP(E28)) -> 5402.8128 | G28: =IF(A28="","",IF(B28="",NA(),B28-F28)) -> 29.187169 | H28: =IF(A28="","",IF(B28="",NA(),G28^2)) -> 851.89086 | M28: =-$I$3 -> -212.07954 | N28: =$I$3 -> 212.07954 | P28: 4 | Q28: =IF(B28="",0,+Q27+ABS(G28)) -> 243.15372 | R28: =IF(B28="",0,+R27+G28^2) -> 19990.103 | S28: =IF(C28>$C$15,0,IF(ABS(G28)>=$I$3,1,0)) -> 0 | T28: =SUM($S$26:S29) -> 0
A29: 2026 | C29: =IF(A29="","",A29) -> 2026 | D29: =IF(A29="","",IF(B29="",NA(),LN(B29))) -> #N/A | E29: =IF(A29="","",$N$17+$N$18*C29) -> 8.6292258 | F29: =IF(A29="","",EXP(E29)) -> 5592.7465 | G29: =IF(A29="","",IF(B29="",NA(),B29-F29)) -> #N/A | H29: =IF(A29="","",IF(B29="",NA(),G29^2)) -> #N/A | M29: =-$I$3 -> -212.07954 | N29: =$I$3 -> 212.07954 | P29: 5 | Q29: =IF(B29="",0,+Q28+ABS(G29)) -> 0 | R29: =IF(B29="",0,+R28+G29^2) -> 0 | S29: =IF(C29>$C$15,0,IF(ABS(G29)>=$I$3,1,0)) -> 0 | T29: =SUM($S$26:S30) -> 0
A30: 2036 | C30: =IF(A30="","",A30) -> 2036 | D30: =IF(A30="","",IF(B30="",NA(),LN(B30))) -> #N/A | E30: =IF(A30="","",$N$17+$N$18*C30) -> 8.6676155 | F30: =IF(A30="","",EXP(E30)) -> 5811.6252 | G30: =IF(A30="","",IF(B30="",NA(),B30-F30)) -> #N/A | H30: =IF(A30="","",IF(B30="",NA(),G30^2)) -> #N/A | M30: =-$I$3 -> -212.07954 | N30: =$I$3 -> 212.07954 | P30: 6 | Q30: =IF(B30="",0,+Q29+ABS(G30)) -> 0 | R30: =IF(B30="",0,+R29+G30^2) -> 0 | S30: =IF(C30>$C$15,0,IF(ABS(G30)>=$I$3,1,0)) -> 0 | T30: =SUM($S$26:S31) -> 0
A31: 2046 | C31: =IF(A31="","",A31) -> 2046 | D31: =IF(A31="","",IF(B31="",NA(),LN(B31))) -> #N/A | E31: =IF(A31="","",$N$17+$N$18*C31) -> 8.7060053 | F31: =IF(A31="","",EXP(E31)) -> 6039.0699 | G31: =IF(A31="","",IF(B31="",NA(),B31-F31)) -> #N/A | H31: =IF(A31="","",IF(B31="",NA(),G31^2)) -> #N/A | M31: =-$I$3 -> -212.07954 | N31: =$I$3 -> 212.07954 | P31: 7 | Q31: =IF(B31="",0,+Q30+ABS(G31)) -> 0 | R31: =IF(B31="",0,+R30+G31^2) -> 0 | S31: =IF(C31>$C$15,0,IF(ABS(G31)>=$I$3,1,0)) -> 0 | T31: =SUM($S$26:S32) -> 0
C32: =IF(A32="","",A32) | D32: =IF(A32="","",IF(B32="",NA(),LN(B32))) | E32: =IF(A32="","",$N$17+$N$18*C32) | F32: =IF(A32="","",EXP(E32)) | G32: =IF(A32="","",IF(B32="",NA(),B32-F32)) | H32: =IF(A32="","",IF(B32="",NA(),G32^2)) | M32: =-$I$3 -> -212.07954 | N32: =$I$3 -> 212.07954 | P32: 8 | Q32: =IF(B32="",0,+Q31+ABS(G32)) -> 0 | R32: =IF(B32="",0,+R31+G32^2) -> 0 | S32: =IF(C32>$C$15,0,IF(ABS(G32)>=$I$3,1,0)) -> 0 | T32: =SUM($S$26:S33) -> 0
C33: =IF(A33="","",A33) | D33: =IF(A33="","",IF(B33="",NA(),LN(B33))) | E33: =IF(A33="","",$N$17+$N$18*C33) | F33: =IF(A33="","",EXP(E33)) | G33: =IF(A33="","",IF(B33="",NA(),B33-F33)) | H33: =IF(A33="","",IF(B33="",NA(),G33^2)) | M33: =-$I$3 -> -212.07954 | N33: =$I$3 -> 212.07954 | P33: 9 | Q33: =IF(B33="",0,+Q32+ABS(G33)) -> 0 | R33: =IF(B33="",0,+R32+G33^2) -> 0 | S33: =IF(C33>$C$15,0,IF(ABS(G33)>=$I$3,1,0)) -> 0 | T33: =SUM($S$26:S34) -> 0
C34: =IF(A34="","",A34) | D34: =IF(A34="","",IF(B34="",NA(),LN(B34))) | E34: =IF(A34="","",$N$17+$N$18*C34) | F34: =IF(A34="","",EXP(E34)) | G34: =IF(A34="","",IF(B34="",NA(),B34-F34)) | H34: =IF(A34="","",IF(B34="",NA(),G34^2)) | M34: =-$I$3 -> -212.07954 | N34: =$I$3 -> 212.07954 | P34: 10 | Q34: =IF(C34>$C$15,0,+Q33+ABS(G34)) -> 0 | R34: =IF(B34="",0,+R33+G34^2) -> 0 | S34: =IF(C34>$C$15,0,IF(ABS(G34)>=$I$3,1,0)) -> 0 | T34: =SUM($S$26:S35) -> 0
C35: =IF(A35="","",A35) | D35: =IF(A35="","",IF(B35="",NA(),LN(B35))) | E35: =IF(A35="","",$N$17+$N$18*C35) | F35: =IF(A35="","",EXP(E35)) | G35: =IF(A35="","",IF(B35="",NA(),B35-F35)) | H35: =IF(A35="","",IF(B35="",NA(),G35^2)) | M35: =-$I$3 -> -212.07954 | N35: =$I$3 -> 212.07954 | P35: 11 | Q35: =IF(C35>$C$15,0,+Q34+ABS(G35)) -> 0 | R35: =IF(B35="",0,+R34+G35^2) -> 0 | S35: =IF(C35>$C$15,0,IF(ABS(G35)>=$I$3,1,0)) -> 0 | T35: =SUM($S$26:S36) -> 0
C36: =IF(A36="","",A36) | D36: =IF(A36="","",IF(B36="",NA(),LN(B36))) | E36: =IF(A36="","",$N$17+$N$18*C36) | F36: =IF(A36="","",EXP(E36)) | G36: =IF(A36="","",IF(B36="",NA(),B36-F36)) | H36: =IF(A36="","",IF(B36="",NA(),G36^2)) | M36: =-$I$3 -> -212.07954 | N36: =$I$3 -> 212.07954 | P36: 12 | Q36: =IF(C36>$C$15,0,+Q35+ABS(G36)) -> 0 | R36: =IF(B36="",0,+R35+G36^2) -> 0 | S36: =IF(C36>$C$15,0,IF(ABS(G36)>=$I$3,1,0)) -> 0 | T36: =SUM($S$26:S37) -> 0
C37: =IF(A37="","",A37) | D37: =IF(A37="","",IF(B37="",NA(),LN(B37))) | E37: =IF(A37="","",$N$17+$N$18*C37) | F37: =IF(A37="","",EXP(E37)) | G37: =IF(A37="","",IF(B37="",NA(),B37-F37)) | H37: =IF(A37="","",IF(B37="",NA(),G37^2)) | M37: =-$I$3 -> -212.07954 | N37: =$I$3 -> 212.07954 | P37: 13 | Q37: =IF(C37>$C$15,0,+Q36+ABS(G37)) -> 0 | R37: =IF(B37="",0,+R36+G37^2) -> 0 | S37: =IF(C37>$C$15,0,IF(ABS(G37)>=$I$3,1,0)) -> 0 | T37: =SUM($S$26:S38) -> 0
C38: =IF(A38="","",A38) | D38: =IF(A38="","",IF(B38="",NA(),LN(B38))) | E38: =IF(A38="","",$N$17+$N$18*C38) | F38: =IF(A38="","",EXP(E38)) | G38: =IF(A38="","",IF(B38="",NA(),B38-F38)) | H38: =IF(A38="","",IF(B38="",NA(),G38^2)) | M38: =-$I$3 -> -212.07954 | N38: =$I$3 -> 212.07954 | P38: 14 | Q38: =IF(C38>$C$15,0,+Q37+ABS(G38)) -> 0 | R38: =IF(B38="",0,+R37+G38^2) -> 0 | S38: =IF(C38>$C$15,0,IF(ABS(G38)>=$I$3,1,0)) -> 0 | T38: =SUM($S$26:S39) -> 0
C39: =IF(A39="","",A39) | D39: =IF(A39="","",IF(B39="",NA(),LN(B39))) | E39: =IF(A39="","",$N$17+$N$18*C39) | F39: =IF(A39="","",EXP(E39)) | G39: =IF(A39="","",IF(B39="",NA(),B39-F39)) | H39: =IF(A39="","",IF(B39="",NA(),G39^2)) | M39: =-$I$3 -> -212.07954 | N39: =$I$3 -> 212.07954 | P39: 15 | Q39: =IF(C39>$C$15,0,+Q38+ABS(G39)) -> 0 | R39: =IF(B39="",0,+R38+G39^2) -> 0 | S39: =IF(C39>$C$15,0,IF(ABS(G39)>=$I$3,1,0)) -> 0 | T39: =SUM($S$26:S40) -> 0
C40: =IF(A40="","",A40) | D40: =IF(A40="","",IF(B40="",NA(),LN(B40))) | E40: =IF(A40="","",$N$17+$N$18*C40) | F40: =IF(A40="","",EXP(E40)) | G40: =IF(A40="","",IF(B40="",NA(),B40-F40)) | H40: =IF(A40="","",IF(B40="",NA(),G40^2)) | M40: =-$I$3 -> -212.07954 | N40: =$I$3 -> 212.07954 | P40: 16 | Q40: =IF(C40>$C$15,0,+Q39+ABS(G40)) -> 0 | R40: =IF(B40="",0,+R39+G40^2) -> 0 | S40: =IF(C40>$C$15,0,IF(ABS(G40)>=$I$3,1,0)) -> 0 | T40: =SUM($S$26:S41) -> 0
C41: =IF(A41="","",A41) | D41: =IF(A41="","",IF(B41="",NA(),LN(B41))) | E41: =IF(A41="","",$N$17+$N$18*C41) | F41: =IF(A41="","",EXP(E41)) | G41: =IF(A41="","",IF(B41="",NA(),B41-F41)) | H41: =IF(A41="","",IF(B41="",NA(),G41^2)) | M41: =-$I$3 -> -212.07954 | N41: =$I$3 -> 212.07954 | P41: 17 | Q41: =IF(C41>$C$15,0,+Q40+ABS(G41)) -> 0 | R41: =IF(B41="",0,+R40+G41^2) -> 0 | S41: =IF(C41>$C$15,0,IF(ABS(G41)>=$I$3,1,0)) -> 0 | T41: =SUM($S$26:S42) -> 0
...

Sheet Logaritmico
A1: LOGARITMICO | D1: IBM World-wide sales | G1: INTERMEDIATE CALCULATIONS: | M1: Resumen
A2: Logaritmica regression on time | G2: RMSE (Square root of MSE) | I2: =IF(C15=0,0,SQRT(I6)) -> 72.167923
A3: Y = a + b*ln(t) | G3: 3 X RMSE | I3: =3*I2 -> 216.50377 | M3: Estadísticas de la regresión
A4: Select Tools, Data Analysis, Regression. Enter ranges as follows: | M4: Coeficiente de correlación múltiple | N4: 0.9203446
A5: Y range includes column B, X range includes column D (mismo tamaño de la columna B), Output range = M1. | G5: Warm-up SSE | I5: =VLOOKUP($C$10,$P$25:$R$120,3) -> 20832.837 | M5: Coeficiente de determinación R^2 | N5: 0.84703417
A6: Ensure number of data selected for Y and X ranges agree with the | G6: Warm-up MSE | I6: =I5/$C$10 -> 5208.2091 | M6: R^2 ajustado | N6: 0.77055126
A7: nbr. of warm-up data entered in cell C10. | G7: Forecasting SSE | I7: =VLOOKUP($C$15,$P$25:$R$120,3) -> 20832.837 | M7: Error típico | N7: 102.06086
G8: Fcst SSE - Warm-up SSE | I8: =I7-I5 -> 0 | M8: Observaciones | N8: 4
A9: INPUT: | G9: Nbr. of forecast periods | I9: =$C$15-$C$10 -> 0
A10: Nbr. of warm-up data | C10: 4 | G10: Forecasting MSE | I10: =IF(I9=0,0,+I8/I9) -> 0 | M10: ANÁLISIS DE VARIANZA
A11: Last period to forecast | C11: 2046 | N11: Grados de libertad | O11: Suma de cuadrados | P11: Promedio de los cuadrados | Q11: F | R11: Valor crítico de F
G12: Warm-up Sum abs. err. | I12: =VLOOKUP($C$10,$P$25:$R$120,2) -> 248.31702 | M12: Regresión | N12: 1 | O12: 115359.91 | P12: 115359.91 | Q12: 11.074816 | R12: 0.079655405
G13: Warm-up MAD | I13: =I12/$C$10 -> 62.079254 | M13: Residuos | N13: 2 | O13: 20832.837 | P13: 10416.418
A14: OUTPUT: | G14: Forecasting Sum abs. err. | I14: =VLOOKUP($C$15,$P$25:$R$120,2) -> 248.31702 | M14: Total | N14: 3 | O14: 136192.75
A15: Number of data | C15: =COUNT(B25:B120) -> 4 | G15: Fcst Sum abs. - Warm-up Sum abs. | I15: =I14-I12 -> 0
A16: Nbr. of outliers | C16: =VLOOKUP(C15,P25:T120,5) -> 0 | G16: Nbr. of forecast periods | I16: =$C$15-$C$10 -> 0 | N16: Coeficientes | O16: Error típico | P16: Estadístico t | Q16: Probabilidad | R16: Inferior 95% | S16: Superior 95% | T16: Inferior 95.0% | U16: Superior 95.0%
A17: Warm-up MSE | C17: =IF(C10=0,0,+I6) -> 5208.2091 | G17: Forecasting MAD | I17: =IF(I16=0,0,+I15/I16) -> 0 | M17: Intercepción | N17: -298327.77 | O17: 91199.248 | P17: -3.2711648 | Q17: 0.082107781 | R17: -690726.47 | S17: 94070.92 | T17: -690726.47 | U17: 94070.92
A18: Forecasting MSE | C18: =IF(C15=0,0,+I10) -> 0 | G18: Last forecast at period | I18: =C11 -> 2046 | M18: Variable X 1 | N18: 39915.164 | O18: 11994.155 | P18: 3.3278846 | Q18: 0.079655405 | R18: -11691.52 | S18: 91521.849 | T18: -11691.52 | U18: 91521.849
A19: Warm-up MAD | C19: =IF(C10=0,0,+I13) -> 62.079254
A20: Forecasting MAD | C20: =IF(C15=0,0,+I17) -> 0
B22: Regression ranges
B23: Y range | D23: X range | M23: Outlier | Q23: Sum abs | R23: Sum | S23: Outlier | T23: Sum
A24: Mon/yr. | B24: Data | C24: t | D24: ln(t) | E24: Est Y | F24: e = Y - Est Y | G24: e^2 | M24: Lower control | N24: Upper control | P24: t | Q24: errors | R24: error^2 | S24: Indicator | T24: nbr outliers
A25: 1993 | B25: 4963 | C25: =IF(A25="","",A25) -> 1993 | D25: =IF(A25="","",LN(C25)) -> 7.5973963 | E25: =IF(A25="","",$N$17+$N$18*D25) -> 4923.547 | F25: =IF(A25="","",IF(B25="",NA(),B25-E25)) -> 39.453002 | G25: =IF(A25="","",IF(B25="",NA(),F25^2)) -> 1556.5393 | M25: =-$I$3 -> -216.50377 | N25: =$I$3 -> 216.50377 | P25: 1 | Q25: =ABS(F25) -> 39.453002 | R25: =F25^2 -> 1556.5393 | S25: =IF(C25>$C$15,0,IF(ABS(G25)>=$I$3,1,0)) -> 0 | T25: =SUM($S$26:S26) -> 0
A26: 2005 | B26: 5039 | C26: =IF(A26="","",A26) -> 2005 | D26: =IF(A26="","",LN(C26)) -> 7.6033993 | E26: =IF(A26="","",$N$17+$N$18*D26) -> 5163.1585 | F26: =IF(A26="","",IF(B26="",NA(),B26-E26)) -> -124.15851 | G26: =IF(A26="","",IF(B26="",NA(),F26^2)) -> 15415.335 | M26: =-$I$3 -> -216.50377 | N26: =$I$3 -> 216.50377 | P26: 2 | Q26: =IF(B26="",0,+Q25+ABS(F26)) -> 163.61151 | R26: =IF(B26="",0,+R25+F26^2) -> 16971.875 | S26: =IF(C26>$C$15,0,IF(ABS(G26)>=$I$3,1,0)) -> 0 | T26: =SUM($S$26:S27) -> 0
A27: 2007 | B27: 5257 | C27: =IF(A27="","",A27) -> 2007 | D27: =IF(A27="","",LN(C27)) -> 7.6043963 | E27: =IF(A27="","",$N$17+$N$18*D27) -> 5202.9543 | F27: =IF(A27="","",IF(B27="",NA(),B27-E27)) -> 54.045711 | G27: =IF(A27="","",IF(B27="",NA(),F27^2)) -> 2920.9389 | M27: =-$I$3 -> -216.50377 | N27: =$I$3 -> 216.50377 | P27: 3 | Q27: =IF(B27="",0,+Q26+ABS(F27)) -> 217.65722 | R27: =IF(B27="",0,+R26+F27^2) -> 19892.813 | S27: =IF(C27>$C$15,0,IF(ABS(G27)>=$I$3,1,0)) -> 0 | T27: =SUM($S$26:S28) -> 0
A28: 2017 | B28: 5432 | C28: =IF(A28="","",A28) -> 2017 | D28: =IF(A28="","",LN(C28)) -> 7.6093665 | E28: =IF(A28="","",$N$17+$N$18*D28) -> 5401.3402 | F28: =IF(A28="","",IF(B28="",NA(),B28-E28)) -> 30.659795 | G28: =IF(A28="","",IF(B28="",NA(),F28^2)) -> 940.02305 | M28: =-$I$3 -> -216.50377 | N28: =$I$3 -> 216.50377 | P28: 4 | Q28: =IF(B28="",0,+Q27+ABS(F28)) -> 248.31702 | R28: =IF(B28="",0,+R27+F28^2) -> 20832.837 | S28: =IF(C28>$C$15,0,IF(ABS(G28)>=$I$3,1,0)) -> 0 | T28: =SUM($S$26:S29) -> 0
A29: 2026 | C29: =IF(A29="","",A29) -> 2026 | D29: =IF(A29="","",LN(C29)) -> 7.6138187 | E29: =IF(A29="","",$N$17+$N$18*D29) -> 5579.0484 | F29: =IF(A29="","",IF(B29="",NA(),B29-E29)) -> #N/A | G29: =IF(A29="","",IF(B29="",NA(),F29^2)) -> #N/A | M29: =-$I$3 -> -216.50377 | N29: =$I$3 -> 216.50377 | P29: 5 | Q29: =IF(B29="",0,+Q28+ABS(F29)) -> 0 | R29: =IF(B29="",0,+R28+F29^2) -> 0 | S29: =IF(C29>$C$15,0,IF(ABS(G29)>=$I$3,1,0)) -> 0 | T29: =SUM($S$26:S30) -> 0
A30: 2036 | C30: =IF(A30="","",A30) -> 2036 | D30: =IF(A30="","",LN(C30)) -> 7.6187424 | E30: =IF(A30="","",$N$17+$N$18*D30) -> 5775.5784 | F30: =IF(A30="","",IF(B30="",NA(),B30-E30)) -> #N/A | G30: =IF(A30="","",IF(B30="",NA(),F30^2)) -> #N/A | M30: =-$I$3 -> -216.50377 | N30: =$I$3 -> 216.50377 | P30: 6 | Q30: =IF(B30="",0,+Q29+ABS(F30)) -> 0 | R30: =IF(B30="",0,+R29+F30^2) -> 0 | S30: =IF(C30>$C$15,0,IF(ABS(G30)>=$I$3,1,0)) -> 0 | T30: =SUM($S$26:S31) -> 0
A31: 2046 | C31: =IF(A31="","",A31) -> 2046 | D31: =IF(A31="","",LN(C31)) -> 7.6236419 | E31: =IF(A31="","",$N$17+$N$18*D31) -> 5971.1455 | F31: =IF(A31="","",IF(B31="",NA(),B31-E31)) -> #N/A | G31: =IF(A31="","",IF(B31="",NA(),F31^2)) -> #N/A | M31: =-$I$3 -> -216.50377 | N31: =$I$3 -> 216.50377 | P31: 7 | Q31: =IF(B31="",0,+Q30+ABS(F31)) -> 0 | R31: =IF(B31="",0,+R30+F31^2) -> 0 | S31: =IF(C31>$C$15,0,IF(ABS(G31)>=$I$3,1,0)) -> 0 | T31: =SUM($S$26:S32) -> 0
C32: =IF(A32="","",A32) | D32: =IF(A32="","",LN(C32)) | E32: =IF(A32="","",$N$17+$N$18*D32) | F32: =IF(A32="","",IF(B32="",NA(),B32-E32)) | G32: =IF(A32="","",IF(B32="",NA(),F32^2)) | H32: =IF(A32="","",IF(B32="",NA(),G32^2)) | M32: =-$I$3 -> -216.50377 | N32: =$I$3 -> 216.50377 | P32: 8 | Q32: =IF(B32="",0,+Q31+ABS(F32)) -> 0 | R32: =IF(B32="",0,+R31+F32^2) -> 0 | S32: =IF(C32>$C$15,0,IF(ABS(G32)>=$I$3,1,0)) -> 0 | T32: =SUM($S$26:S33) -> 0
C33: =IF(A33="","",A33) | D33: =IF(A33="","",LN(C33)) | E33: =IF(A33="","",$N$17+$N$18*D33) | F33: =IF(A33="","",IF(B33="",NA(),B33-E33)) | G33: =IF(A33="","",IF(B33="",NA(),F33^2)) | H33: =IF(A33="","",IF(B33="",NA(),G33^2)) | M33: =-$I$3 -> -216.50377 | N33: =$I$3 -> 216.50377 | P33: 9 | Q33: =IF(B33="",0,+Q32+ABS(F33)) -> 0 | R33: =IF(B33="",0,+R32+F33^2) -> 0 | S33: =IF(C33>$C$15,0,IF(ABS(G33)>=$I$3,1,0)) -> 0 | T33: =SUM($S$26:S34) -> 0
C34: =IF(A34="","",A34) | D34: =IF(A34="","",LN(C34)) | E34: =IF(A34="","",$N$17+$N$18*D34) | F34: =IF(A34="","",IF(B34="",NA(),B34-E34)) | G34: =IF(A34="","",IF(B34="",NA(),F34^2)) | H34: =IF(A34="","",IF(B34="",NA(),G34^2)) | M34: =-$I$3 -> -216.50377 | N34: =$I$3 -> 216.50377 | P34: 10 | Q34: =IF(B34="",0,+Q33+ABS(F34)) -> 0 | R34: =IF(B34="",0,+R33+F34^2) -> 0 | S34: =IF(C34>$C$15,0,IF(ABS(G34)>=$I$3,1,0)) -> 0 | T34: =SUM($S$26:S35) -> 0
C35: =IF(A35="","",A35) | D35: =IF(A35="","",LN(C35)) | E35: =IF(A35="","",$N$17+$N$18*D35) | F35: =IF(A35="","",IF(B35="",NA(),B35-E35)) | G35: =IF(A35="","",IF(B35="",NA(),F35^2)) | H35: =IF(A35="","",IF(B35="",NA(),G35^2)) | M35: =-$I$3 -> -216.50377 | N35: =$I$3 -> 216.50377 | P35: 11 | Q35: =IF(B35="",0,+Q34+ABS(F35)) -> 0 | R35: =IF(B35="",0,+R34+F35^2) -> 0 | S35: =IF(C35>$C$15,0,IF(ABS(G35)>=$I$3,1,0)) -> 0 | T35: =SUM($S$26:S36) -> 0
C36: =IF(A36="","",A36) | D36: =IF(A36="","",LN(C36)) | E36: =IF(A36="","",$N$17+$N$18*D36) | F36: =IF(A36="","",IF(B36="",NA(),B36-E36)) | G36: =IF(A36="","",IF(B36="",NA(),F36^2)) | H36: =IF(A36="","",IF(B36="",NA(),G36^2)) | M36: =-$I$3 -> -216.50377 | N36: =$I$3 -> 216.50377 | P36: 12 | Q36: =IF(B36="",0,+Q35+ABS(F36)) -> 0 | R36: =IF(B36="",0,+R35+F36^2) -> 0 | S36: =IF(C36>$C$15,0,IF(ABS(G36)>=$I$3,1,0)) -> 0 | T36: =SUM($S$26:S37) -> 0
C37: =IF(A37="","",A37) | D37: =IF(A37="","",LN(C37)) | E37: =IF(A37="","",$N$17+$N$18*D37) | F37: =IF(A37="","",IF(B37="",NA(),B37-E37)) | G37: =IF(A37="","",IF(B37="",NA(),F37^2)) | H37: =IF(A37="","",IF(B37="",NA(),G37^2)) | M37: =-$I$3 -> -216.50377 | N37: =$I$3 -> 216.50377 | P37: 13 | Q37: =IF(B37="",0,+Q36+ABS(F37)) -> 0 | R37: =IF(B37="",0,+R36+F37^2) -> 0 | S37: =IF(C37>$C$15,0,IF(ABS(G37)>=$I$3,1,0)) -> 0 | T37: =SUM($S$26:S38) -> 0
C38: =IF(A38="","",A38) | D38: =IF(A38="","",LN(C38)) | E38: =IF(A38="","",$N$17+$N$18*D38) | F38: =IF(A38="","",IF(B38="",NA(),B38-E38)) | G38: =IF(A38="","",IF(B38="",NA(),F38^2)) | H38: =IF(A38="","",IF(B38="",NA(),G38^2)) | M38: =-$I$3 -> -216.50377 | N38: =$I$3 -> 216.50377 | P38: 14 | Q38: =IF(B38="",0,+Q37+ABS(F38)) -> 0 | R38: =IF(B38="",0,+R37+F38^2) -> 0 | S38: =IF(C38>$C$15,0,IF(ABS(G38)>=$I$3,1,0)) -> 0 | T38: =SUM($S$26:S39) -> 0
C39: =IF(A39="","",A39) | D39: =IF(A39="","",LN(C39)) | E39: =IF(A39="","",$N$17+$N$18*D39) | F39: =IF(A39="","",IF(B39="",NA(),B39-E39)) | G39: =IF(A39="","",IF(B39="",NA(),F39^2)) | H39: =IF(A39="","",IF(B39="",NA(),G39^2)) | M39: =-$I$3 -> -216.50377 | N39: =$I$3 -> 216.50377 | P39: 15 | Q39: =IF(B39="",0,+Q38+ABS(F39)) -> 0 | R39: =IF(B39="",0,+R38+F39^2) -> 0 | S39: =IF(C39>$C$15,0,IF(ABS(G39)>=$I$3,1,0)) -> 0 | T39: =SUM($S$26:S40) -> 0
C40: =IF(A40="","",A40) | D40: =IF(A40="","",LN(C40)) | E40: =IF(A40="","",$N$17+$N$18*D40) | F40: =IF(A40="","",IF(B40="",NA(),B40-E40)) | G40: =IF(A40="","",IF(B40="",NA(),F40^2)) | H40: =IF(A40="","",IF(B40="",NA(),G40^2)) | M40: =-$I$3 -> -216.50377 | N40: =$I$3 -> 216.50377 | P40: 16 | Q40: =IF(B40="",0,+Q39+ABS(F40)) -> 0 | R40: =IF(B40="",0,+R39+F40^2) -> 0 | S40: =IF(C40>$C$15,0,IF(ABS(G40)>=$I$3,1,0)) -> 0 | T40: =SUM($S$26:S41) -> 0
C41: =IF(A41="","",A41) | D41: =IF(A41="","",LN(C41)) | E41: =IF(A41="","",$N$17+$N$18*D41) | F41: =IF(A41="","",IF(B41="",NA(),B41-E41)) | G41: =IF(A41="","",IF(B41="",NA(),F41^2)) | H41: =IF(A41="","",IF(B41="",NA(),G41^2)) | M41: =-$I$3 -> -216.50377 | N41: =$I$3 -> 216.50377 | P41: 17 | Q41: =IF(B41="",0,+Q40+ABS(F41)) -> 0 | R41: =IF(B41="",0,+R40+F41^2) -> 0 | S41: =IF(C41>$C$15,0,IF(ABS(G41)>=$I$3,1,0)) -> 0 | T41: =SUM($S$26:S42) -> 0
...

Sheet Polinomica_2
A1: POLINOMICA_2 | D1: IBM World-wide sales | G1: INTERMEDIATE CALCULATIONS: | M1: Resumen
A2: Polinomica 2do Grado regression on time | G2: RMSE (Square root of MSE) | I2: =IF(C15=0,0,SQRT(I6)) -> 62.334487
A3: Y = a + b*t + c*t^2 | G3: 3 X RMSE | I3: =3*I2 -> 187.00346 | M3: Estadísticas de la regresión
A4: Select Tools, Data Analysis, Regression. Enter ranges as follows: | M4: Coeficiente de correlación múltiple | N4: 0.94121184
A5: Y range includes column B, X range includes column C y D (mismo tamaño de la columna B), Output range = M1. | G5: Warm-up SSE | I5: =VLOOKUP($C$10,$P$25:$R$120,3) -> 15542.353 | M5: Coeficiente de determinación R^2 | N5: 0.88587973
A6: Ensure number of data selected for Y and X ranges agree with the | G6: Warm-up MSE | I6: =I5/$C$10 -> 3885.5883 | M6: R^2 ajustado | N6: 0.65763919
A7: nbr. of warm-up data entered in cell C10. | G7: Forecasting SSE | I7: =VLOOKUP($C$15,$P$25:$R$120,3) -> 15542.353 | M7: Error típico | N7: 124.66897
G8: Fcst SSE - Warm-up SSE | I8: =I7-I5 -> 0 | M8: Observaciones | N8: 4
A9: INPUT: | G9: Nbr. of forecast periods | I9: =$C$15-$C$10 -> 0
A10: Nbr. of warm-up data | C10: 4 | G10: Forecasting MSE | I10: =IF(I9=0,0,+I8/I9) -> 0 | M10: ANÁLISIS DE VARIANZA
A11: Last period to forecast | C11: 2046 | N11: Grados de libertad | O11: Suma de cuadrados | P11: Promedio de los cuadrados | Q11: F | R11: Valor crítico de F
G12: Warm-up Sum abs. err. | I12: =VLOOKUP($C$10,$P$25:$R$120,2) -> 15542.353 | M12: Regresión | N12: 2 | O12: 120650.4 | P12: 60325.198 | Q12: 3.8813426 | R12: 0.33781692
G13: Warm-up MAD | I13: =I12/$C$10 -> 3885.5883 | M13: Residuos | N13: 1 | O13: 15542.353 | P13: 15542.353
A14: OUTPUT: | G14: Forecasting Sum abs. err. | I14: =VLOOKUP($C$15,$P$25:$R$120,2) -> 15542.353 | M14: Total | N14: 3 | O14: 136192.75
A15: Number of data | C15: =COUNT(B25:B120) -> 4 | G15: Fcst Sum abs. - Warm-up Sum abs. | I15: =I14-I12 -> 0
A16: Nbr. of outliers | C16: =VLOOKUP(C15,P25:T120,5) -> 0 | G16: Nbr. of forecast periods | I16: =$C$15-$C$10 -> 0 | N16: Coeficientes | O16: Error típico | P16: Estadístico t | Q16: Probabilidad | R16: Inferior 95% | S16: Superior 95% | T16: Inferior 95.0% | U16: Superior 95.0%
A17: Warm-up MSE | C17: =IF(C10=0,0,+I6) -> 3885.5883 | G17: Forecasting MAD | I17: =IF(I16=0,0,+I15/I16) -> 0 | M17: Intercepción | N17: 2006822.2 | O17: 3533551.1 | P17: 0.56793353 | Q17: 0.67118116 | R17: -42891202 | S17: 46904846 | T17: -42891202 | U17: 46904846
A18: Forecasting MSE | C18: =IF(C15=0,0,+I10) -> 0 | G18: Last forecast at period | I18: =C11 -> 2046 | M18: Variable X 1 | N18: -2016.865 | O18: 3525.1977 | P18: -0.57212819 | Q18: 0.66916566 | R18: -46808.749 | S18: 42775.019 | T18: -46808.749 | U18: 42775.019
A19: Warm-up MAD | C19: =IF(C10=0,0,+I13) -> 3885.5883 | M19: Variable X 2 | N19: 0.50798632 | O19: 0.87920376 | P19: 0.57777996 | Q19: 0.66646154 | R19: -10.663357 | S19: 11.679329 | T19: -10.663357 | U19: 11.679329
A20: Forecasting MAD | C20: =IF(C15=0,0,+I17) -> 0
B22: Regression ranges
B23: Y range | C23: X range | M23: Outlier | Q23: Sum abs | R23: Sum | S23: Outlier | T23: Sum
A24: Mon/yr. | B24: Data | C24: t | D24: t^2 | E24: Est Y | F24: e = Y - Est Y | G24: e^2 | M24: Lower control | N24: Upper control | P24: t | Q24: errors | R24: error^2 | S24: Indicator | T24: nbr outliers
A25: 1993 | B25: 4963 | C25: =IF(A25="","",A25) -> 1993 | D25: =IF(C25="","",C25^2) -> 3972049 | E25: =IF(C25="","",$N$17+$N$18*C25+$N$19*D25) -> 4956.8152 | F25: =IF(A25="","",IF(B25="",NA(),B25-E25)) -> 6.1847805 | G25: =IF(A25="","",IF(B25="",NA(),F25^2)) -> 38.251509 | M25: =-$I$3 -> -187.00346 | N25: =$I$3 -> 187.00346 | P25: 1 | Q25: =ABS(G25) -> 38.251509 | R25: =F25^2 -> 38.251509 | S25: =IF(C25>$C$15,0,IF(ABS(G25)>=$I$3,1,0)) -> 0 | T25: =SUM($S$26:S26) -> 0
A26: 2005 | B26: 5039 | C26: =IF(A26="","",A26) -> 2005 | D26: =IF(C26="","",C26^2) -> 4020025 | E26: =IF(C26="","",$N$17+$N$18*C26+$N$19*D26) -> 5125.5869 | F26: =IF(A26="","",IF(B26="",NA(),B26-E26)) -> -86.586927 | G26: =IF(A26="","",IF(B26="",NA(),F26^2)) -> 7497.2959 | M26: =-$I$3 -> -187.00346 | N26: =$I$3 -> 187.00346 | P26: 2 | Q26: =IF(B26="",0,+Q25+ABS(G26)) -> 7535.5474 | R26: =IF(B26="",0,+R25+F26^2) -> 7535.5474 | S26: =IF(C26>$C$15,0,IF(ABS(G26)>=$I$3,1,0)) -> 0 | T26: =SUM($S$26:S27) -> 0
A27: 2007 | B27: 5257 | C27: =IF(A27="","",A27) -> 2007 | D27: =IF(C27="","",C27^2) -> 4028049 | E27: =IF(C27="","",$N$17+$N$18*C27+$N$19*D27) -> 5167.9392 | F27: =IF(A27="","",IF(B27="",NA(),B27-E27)) -> 89.060839 | G27: =IF(A27="","",IF(B27="",NA(),F27^2)) -> 7931.833 | M27: =-$I$3 -> -187.00346 | N27: =$I$3 -> 187.00346 | P27: 3 | Q27: =IF(B27="",0,+Q26+ABS(G27)) -> 15467.38 | R27: =IF(B27="",0,+R26+F27^2) -> 15467.38 | S27: =IF(C27>$C$15,0,IF(ABS(G27)>=$I$3,1,0)) -> 0 | T27: =SUM($S$26:S28) -> 0
A28: 2017 | B28: 5432 | C28: =IF(A28="","",A28) -> 2017 | D28: =IF(C28="","",C28^2) -> 4068289 | E28: =IF(C28="","",$N$17+$N$18*C28+$N$19*D28) -> 5440.6587 | F28: =IF(A28="","",IF(B28="",NA(),B28-E28)) -> -8.6586927 | G28: =IF(A28="","",IF(B28="",NA(),F28^2)) -> 74.972959 | M28: =-$I$3 -> -187.00346 | N28: =$I$3 -> 187.00346 | P28: 4 | Q28: =IF(B28="",0,+Q27+ABS(G28)) -> 15542.353 | R28: =IF(B28="",0,+R27+F28^2) -> 15542.353 | S28: =IF(C28>$C$15,0,IF(ABS(G28)>=$I$3,1,0)) -> 0 | T28: =SUM($S$26:S29) -> 0
A29: 2026 | C29: =IF(A29="","",A29) -> 2026 | D29: =IF(C29="","",C29^2) -> 4104676 | E29: =IF(C29="","",$N$17+$N$18*C29+$N$19*D29) -> 5772.9719 | F29: =IF(A29="","",IF(B29="",NA(),B29-E29)) -> #N/A | G29: =IF(A29="","",IF(B29="",NA(),F29^2)) -> #N/A | M29: =-$I$3 -> -187.00346 | N29: =$I$3 -> 187.00346 | P29: 5 | Q29: =IF(B29="",0,+Q28+ABS(G29)) -> 0 | R29: =IF(B29="",0,+R28+F29^2) -> 0 | S29: =IF(C29>$C$15,0,IF(ABS(G29)>=$I$3,1,0)) -> 0 | T29: =SUM($S$26:S30) -> 0
A30: 2036 | C30: =IF(A30="","",A30) -> 2036 | D30: =IF(C30="","",C30^2) -> 4145296 | E30: =IF(C30="","",$N$17+$N$18*C30+$N$19*D30) -> 6238.7263 | F30: =IF(A30="","",IF(B30="",NA(),B30-E30)) -> #N/A | G30: =IF(A30="","",IF(B30="",NA(),F30^2)) -> #N/A | M30: =-$I$3 -> -187.00346 | N30: =$I$3 -> 187.00346 | P30: 6 | Q30: =IF(B30="",0,+Q29+ABS(G30)) -> 0 | R30: =IF(B30="",0,+R29+F30^2) -> 0 | S30: =IF(C30>$C$15,0,IF(ABS(G30)>=$I$3,1,0)) -> 0 | T30: =SUM($S$26:S31) -> 0
A31: 2046 | C31: =IF(A31="","",A31) -> 2046 | D31: =IF(C31="","",C31^2) -> 4186116 | E31: =IF(C31="","",$N$17+$N$18*C31+$N$19*D31) -> 6806.0779 | F31: =IF(A31="","",IF(B31="",NA(),B31-E31)) -> #N/A | G31: =IF(A31="","",IF(B31="",NA(),F31^2)) -> #N/A | M31: =-$I$3 -> -187.00346 | N31: =$I$3 -> 187.00346 | P31: 7 | Q31: =IF(B31="",0,+Q30+ABS(G31)) -> 0 | R31: =IF(B31="",0,+R30+F31^2) -> 0 | S31: =IF(C31>$C$15,0,IF(ABS(G31)>=$I$3,1,0)) -> 0 | T31: =SUM($S$26:S32) -> 0
C32: =IF(A32="","",A32) | D32: =IF(C32="","",C32^2) | E32: =IF(C32="","",$N$17+$N$18*C32+$N$19*D32) | F32: =IF(A32="","",IF(B32="",NA(),B32-E32)) | G32: =IF(A32="","",IF(B32="",NA(),F32^2)) | M32: =-$I$3 -> -187.00346 | N32: =$I$3 -> 187.00346 | P32: 8 | Q32: =IF(B32="",0,+Q31+ABS(G32)) -> 0 | R32: =IF(B32="",0,+R31+F32^2) -> 0 | S32: =IF(C32>$C$15,0,IF(ABS(G32)>=$I$3,1,0)) -> 0 | T32: =SUM($S$26:S33) -> 0
C33: =IF(A33="","",A33) | D33: =IF(C33="","",C33^2) | E33: =IF(C33="","",$N$17+$N$18*C33+$N$19*D33) | F33: =IF(A33="","",IF(B33="",NA(),B33-E33)) | G33: =IF(A33="","",IF(B33="",NA(),F33^2)) | M33: =-$I$3 -> -187.00346 | N33: =$I$3 -> 187.00346 | P33: 9 | Q33: =IF(B33="",0,+Q32+ABS(G33)) -> 0 | R33: =IF(B33="",0,+R32+F33^2) -> 0 | S33: =IF(C33>$C$15,0,IF(ABS(G33)>=$I$3,1,0)) -> 0 | T33: =SUM($S$26:S34) -> 0
C34: =IF(A34="","",A34) | D34: =IF(C34="","",C34^2) | E34: =IF(C34="","",$N$17+$N$18*C34+$N$19*D34) | F34: =IF(A34="","",IF(B34="",NA(),B34-E34)) | G34: =IF(A34="","",IF(B34="",NA(),F34^2)) | M34: =-$I$3 -> -187.00346 | N34: =$I$3 -> 187.00346 | P34: 10 | Q34: =IF(C34>$C$15,0,+Q33+ABS(G34)) -> 0 | R34: =IF(C34>$C$15,0,+R33+G34^2) -> 0 | S34: =IF(C34>$C$15,0,IF(ABS(G34)>=$I$3,1,0)) -> 0 | T34: =SUM($S$26:S35) -> 0
C35: =IF(A35="","",A35) | D35: =IF(C35="","",C35^2) | E35: =IF(C35="","",$N$17+$N$18*C35+$N$19*D35) | F35: =IF(A35="","",IF(B35="",NA(),B35-E35)) | G35: =IF(A35="","",IF(B35="",NA(),F35^2)) | M35: =-$I$3 -> -187.00346 | N35: =$I$3 -> 187.00346 | P35: 11 | Q35: =IF(C35>$C$15,0,+Q34+ABS(G35)) -> 0 | R35: =IF(C35>$C$15,0,+R34+G35^2) -> 0 | S35: =IF(C35>$C$15,0,IF(ABS(G35)>=$I$3,1,0)) -> 0 | T35: =SUM($S$26:S36) -> 0
C36: =IF(A36="","",A36) | D36: =IF(C36="","",C36^2) | E36: =IF(C36="","",$N$17+$N$18*C36+$N$19*D36) | F36: =IF(A36="","",IF(B36="",NA(),B36-E36)) | G36: =IF(A36="","",IF(B36="",NA(),F36^2)) | M36: =-$I$3 -> -187.00346 | N36: =$I$3 -> 187.00346 | P36: 12 | Q36: =IF(C36>$C$15,0,+Q35+ABS(G36)) -> 0 | R36: =IF(C36>$C$15,0,+R35+G36^2) -> 0 | S36: =IF(C36>$C$15,0,IF(ABS(G36)>=$I$3,1,0)) -> 0 | T36: =SUM($S$26:S37) -> 0
C37: =IF(A37="","",A37) | D37: =IF(C37="","",C37^2) | E37: =IF(C37="","",$N$17+$N$18*C37+$N$19*D37) | F37: =IF(A37="","",IF(B37="",NA(),B37-E37)) | G37: =IF(A37="","",IF(B37="",NA(),F37^2)) | M37: =-$I$3 -> -187.00346 | N37: =$I$3 -> 187.00346 | P37: 13 | Q37: =IF(C37>$C$15,0,+Q36+ABS(G37)) -> 0 | R37: =IF(C37>$C$15,0,+R36+G37^2) -> 0 | S37: =IF(C37>$C$15,0,IF(ABS(G37)>=$I$3,1,0)) -> 0 | T37: =SUM($S$26:S38) -> 0
C38: =IF(A38="","",A38) | D38: =IF(C38="","",C38^2) | E38: =IF(C38="","",$N$17+$N$18*C38+$N$19*D38) | F38: =IF(A38="","",IF(B38="",NA(),B38-E38)) | G38: =IF(A38="","",IF(B38="",NA(),F38^2)) | M38: =-$I$3 -> -187.00346 | N38: =$I$3 -> 187.00346 | P38: 14 | Q38: =IF(C38>$C$15,0,+Q37+ABS(G38)) -> 0 | R38: =IF(C38>$C$15,0,+R37+G38^2) -> 0 | S38: =IF(C38>$C$15,0,IF(ABS(G38)>=$I$3,1,0)) -> 0 | T38: =SUM($S$26:S39) -> 0
C39: =IF(A39="","",A39) | D39: =IF(C39="","",C39^2) | E39: =IF(C39="","",$N$17+$N$18*C39+$N$19*D39) | F39: =IF(A39="","",IF(B39="",NA(),B39-E39)) | G39: =IF(A39="","",IF(B39="",NA(),F39^2)) | M39: =-$I$3 -> -187.00346 | N39: =$I$3 -> 187.00346 | P39: 15 | Q39: =IF(C39>$C$15,0,+Q38+ABS(G39)) -> 0 | R39: =IF(C39>$C$15,0,+R38+G39^2) -> 0 | S39: =IF(C39>$C$15,0,IF(ABS(G39)>=$I$3,1,0)) -> 0 | T39: =SUM($S$26:S40) -> 0
C40: =IF(A40="","",A40) | D40: =IF(C40="","",C40^2) | E40: =IF(C40="","",$N$17+$N$18*C40+$N$19*D40) | F40: =IF(A40="","",IF(B40="",NA(),B40-E40)) | G40: =IF(A40="","",IF(B40="",NA(),F40^2)) | M40: =-$I$3 -> -187.00346 | N40: =$I$3 -> 187.00346 | P40: 16 | Q40: =IF(C40>$C$15,0,+Q39+ABS(G40)) -> 0 | R40: =IF(C40>$C$15,0,+R39+G40^2) -> 0 | S40: =IF(C40>$C$15,0,IF(ABS(G40)>=$I$3,1,0)) -> 0 | T40: =SUM($S$26:S41) -> 0
C41: =IF(A41="","",A41) | D41: =IF(C41="","",C41^2) | E41: =IF(C41="","",$N$17+$N$18*C41+$N$19*D41) | F41: =IF(A41="","",IF(B41="",NA(),B41-E41)) | G41: =IF(A41="","",IF(B41="",NA(),F41^2)) | M41: =-$I$3 -> -187.00346 | N41: =$I$3 -> 187.00346 | P41: 17 | Q41: =IF(C41>$C$15,0,+Q40+ABS(G41)) -> 0 | R41: =IF(C41>$C$15,0,+R40+G41^2) -> 0 | S41: =IF(C41>$C$15,0,IF(ABS(G41)>=$I$3,1,0)) -> 0 | T41: =SUM($S$26:S42) -> 0
...

Sheet RESUMEN
A3: Año | B3: Lineal | C3: Potencial | D3: Logaritmico | E3: Polinomica_2 | F3: Exponencial
A4: =+Lineal!A25 -> 1993 | B4: =+Lineal!D25 -> 4923.7595 | C4: =+Potencial!G25 -> 4927.0587 | D4: =+Logaritmico!E25 -> 4923.547 | E4: =+Polinomica_2!E25 -> 4956.8152 | F4: =+Exponencial!F25 -> 4927.2661
A5: =+Lineal!A26 -> 2005 | B5: =+Lineal!D26 -> 5162.7904 | C5: =+Potencial!G26 -> 5159.9294 | D5: =+Logaritmico!E26 -> 5163.1585 | E5: =+Polinomica_2!E26 -> 5125.5869 | F5: =+Exponencial!F26 -> 5159.5636
A6: =+Lineal!A27 -> 2007 | B6: =+Lineal!D27 -> 5202.6289 | C6: =+Potencial!G27 -> 5199.6578 | D6: =+Logaritmico!E27 -> 5202.9543 | E6: =+Polinomica_2!E27 -> 5167.9392 | F6: =+Exponencial!F27 -> 5199.3309
A7: =+Lineal!A28 -> 2017 | B7: =+Lineal!D28 -> 5401.8213 | C7: =+Potencial!G28 -> 5402.3176 | D7: =+Logaritmico!E28 -> 5401.3402 | E7: =+Polinomica_2!E28 -> 5440.6587 | F7: =+Exponencial!F28 -> 5402.8128
A8: =+Lineal!A29 -> 2026 | B8: =+Lineal!D29 -> 5581.0945 | C8: =+Potencial!G29 -> 5590.5521 | D8: =+Logaritmico!E29 -> 5579.0484 | E8: =+Polinomica_2!E29 -> 5772.9719 | F8: =+Exponencial!F29 -> 5592.7465
A9: =+Lineal!A30 -> 2036 | B9: =+Lineal!D30 -> 5780.2869 | C9: =+Potencial!G30 -> 5806.37 | D9: =+Logaritmico!E30 -> 5775.5784 | E9: =+Polinomica_2!E30 -> 6238.7263 | F9: =+Exponencial!F30 -> 5811.6252
A10: =+Lineal!A31 -> 2046 | B10: =+Lineal!D31 -> 5979.4794 | C10: =+Potencial!G31 -> 6029.4003 | D10: =+Logaritmico!E31 -> 5971.1455 | E10: =+Polinomica_2!E31 -> 6806.0779 | F10: =+Exponencial!F31 -> 6039.0699
